<?xml version="1.0"?>
<robot name = "contactcart">
    <material name="grey">
        <color rgba="0.2 0.2 0.2 1.0"/>
    </material>
    <material name="silver">
        <color rgba="0.913725490196 0.913725490196 0.847058823529 1.0"/>
    </material>
    <!-- links section -->>
    <link name="track">
  	    <visual>
    	    <origin xyz="2.5 0 1.5"/>
      	    <geometry>
                <box size="7 0.1 0.1"/>
      	    </geometry>
            <material name = "silver"/>
  	    </visual>
		<inertial>
			<origin xyz = "2.5 0 1.5" />
			<mass value = "10" />
			<inertia ixx = "0.0167" iyy = "40.8" izz = "40.8" ixy = "0" ixz = "0" iyz = "0" />
		</inertial>
    </link>
	<link name = "cart">
		<inertial>
			<origin xyz = "0 0 1.5" />
			<mass value = "1" />
			<inertia ixx = "0.0241" iyy = "0.0241" izz = "0.0417" ixy = "0" ixz = "0" iyz = "0" />
		</inertial>
		<visual>
			<origin xyz = "0 0 0" />
			<geometry>
				<box size = "0.5 0.5 0.2" />
			</geometry>
			<material name = "grey"/>
		</visual>
	</link>
	<link name = "upper_pendulum">
		<inertial>
			<origin xyz = "0 0 -0.5" />
			<mass value = "1" />
			<inertia ixx = "0.083" iyy = "0.083" izz = "0.125" ixy = "0" ixz = "0" iyz = "0" />
		</inertial>
		<visual>
			<origin xyz = "0 0 -0.5" />
			<geometry>
				<cylinder radius = "0.05" length = "1"  />
			</geometry>
            <material name = "grey"/>
		</visual>
	</link>
	<link name = "lower_pendulum">
		<inertial>
			<origin xyz = "0 0 -0.5" />
			<mass value = "1" />
			<inertia ixx = "0.083" iyy = "0.083" izz = "0.125" ixy = "0" ixz = "0" iyz = "0" />
		</inertial>
		<visual>
			<origin xyz = "0 0 -0.5" />
			<geometry>
				<cylinder radius = "0.05" length = "1"  />
			</geometry>
            <material name = "grey"/>
		</visual>
	</link>
    <!--These links are for visualization-->
	<link name="knee_sphere">
		<visual>
        	<origin xyz="0 0 0"/>
          	<geometry>
              <sphere radius="0.05"/>
          	</geometry>
            <material name = "grey"/>
        </visual>
        <inertial>
            <origin xyz="0 0 0"/>
            <mass value = "0.001"/>
            <inertia ixx = "0.0001" iyy = "0.0001" izz = "0.0001" ixy = "0" ixz = "0" iyz = "0" />
        </inertial>
	</link>
	<link name="foot_sphere">
	    <visual>
        	<origin xyz="0 0 0"/>
          	<geometry>
              <sphere radius="0.05"/>
          	</geometry>
            <material name = "grey"/>
        </visual>
        <inertial>
            <origin xyz="0 0 0"/>
            <mass value = "0.001"/>
            <inertia ixx = "0.0001" iyy = "0.0001" izz = "0.0001" ixy = "0" ixz = "0" iyz = "0" />
        </inertial>
	</link>
	<!-- joints section -->>
	<joint name = "slider" type = "prismatic">
		<parent link="track"/>
      	<child link="cart"/>
      	<origin xyz="0 0 1.5"/>
      	<axis xyz = "1 0 0"/>
	</joint>
	<joint name = "hip" type = "revolute">
		<parent link = "cart" />
		<child link = "upper_pendulum" />
		<origin xyz = "0 0 0" />
		<axis xyz = "0 -1 0" />
	</joint>
	<joint name = "knee" type = "revolute">
		<parent link = "upper_pendulum" />
		<child link = "lower_pendulum" />
		<origin xyz = "0 0 -1" />
		<axis xyz = "0 -1 0" />
	</joint>
    <!--These joint are for visualization-->
	<joint name="kneecap" type="fixed">
      <parent link="upper_pendulum"/>
      <child link="knee_sphere"/>
      <origin xyz="0 0 -1"/>
      <axis xyz="1 0 0"/>
	</joint>
	<joint name="footcap" type="fixed">
      <parent link="lower_pendulum"/>
      <child link="foot_sphere"/>
      <origin xyz="0 0 -1"/>
      <axis xyz="1 0 0"/>
	</joint>
    <!-- actuator section -->
    <transmission name = "joint1_transmission">
        <type>transmission_interface/SimpleTransmission</type>
        <joint name="hip"/>
        <actuator name="hip_actuator">
            <mechanicalReduction>1</mechanicalReduction>
        </actuator>
    </transmission>
    <transmission name="knee_actuation">
        <type>transmission_interface/SimpleTransmission</type>
        <joint name="knee"/>
        <actuator name="knee_actuator">
            <mechanicalReduction>1</mechanicalReduction>
        </actuator>
    </transmission>
</robot>